The values used are [-7, 29, 8, 41, 3, 44, -19, 2, 1, 6]
Processing -7
	Calling fun1_1
	Value caused error: 
		Traceback (most recent call last):
		  File ".../gen_log.py", line 72, in queue_processor
		    res = int(gen_stack.fun5(num))
		              ^^^^^^^^^^^^^^^^^^^
		  File ".../gen_stack.py", line 64, in fun5
		    return fun4(x) + 4321
		           ^^^^^^^
		  File ".../gen_stack.py", line 60, in fun4
		    return fun3(x) + 0.1
		           ^^^^^^^
		  File ".../gen_stack.py", line 56, in fun3
		    return fun2(x) * 4.56
		           ^^^^^^^
		  File ".../gen_stack.py", line 52, in fun2
		    return fun1_1(x) - 12
		           ^^^^^^^^^
		  File ".../gen_stack.py", line 41, in fun1_1
		    return fun0_1(x) * 3
		           ^^^^^^^^^
		  File ".../gen_stack.py", line 29, in fun0_1
		    return sqrt(x)
		           ^^^^^^^
		ValueError: math domain error

	Total is 202
	Needs 798 more
	Creating directory: /home/pc/sciebo/Dokumente/Programming/recipe2txt/test/testfiles/permanent/logfiles/gen_log_res
	Creating file: /home/pc/sciebo/Dokumente/Programming/recipe2txt/test/testfiles/permanent/logfiles/gen_log_res/202
Processing 29
	Calling fun1_2
	Value caused ZeroDivisonError: 
		Traceback (most recent call last):
		  File ".../gen_log.py", line 72, in queue_processor
		    res = int(gen_stack.fun5(num))
		              ^^^^^^^^^^^^^^^^^^^
		  File ".../gen_stack.py", line 64, in fun5
		    return fun4(x) + 4321
		           ^^^^^^^
		  File ".../gen_stack.py", line 60, in fun4
		    return fun3(x) + 0.1
		           ^^^^^^^
		  File ".../gen_stack.py", line 56, in fun3
		    return fun2(x) * 4.56
		           ^^^^^^^
		  File ".../gen_stack.py", line 49, in fun2
		    return fun1_2(x * 0)
		           ^^^^^^^^^^^^^
		  File ".../gen_stack.py", line 37, in fun1_2
		    return fun0_2(x) * 10
		           ^^^^^^^^^
		  File ".../gen_stack.py", line 33, in fun0_2
		    return 13 / x
		           ~~~^~~
		ZeroDivisionError: division by zero

	Total is 303
	Needs 697 more
	File cannot be accessed: /root/test/101 (PermissionError(13, 'Permission denied'))
	Total could not be written!
Processing 8
	Calling fun1_1
	Total is 4608
	File cannot be accessed: /root/test/4305 (PermissionError(13, 'Permission denied'))
	Total could not be written!
Processing 41
	Calling fun1_2
	Value caused ZeroDivisonError: 
		Traceback (most recent call last):
		  File ".../gen_log.py", line 72, in queue_processor
		    res = int(gen_stack.fun5(num))
		              ^^^^^^^^^^^^^^^^^^^
		  File ".../gen_stack.py", line 64, in fun5
		    return fun4(x) + 4321
		           ^^^^^^^
		  File ".../gen_stack.py", line 60, in fun4
		    return fun3(x) + 0.1
		           ^^^^^^^
		  File ".../gen_stack.py", line 56, in fun3
		    return fun2(x) * 4.56
		           ^^^^^^^
		  File ".../gen_stack.py", line 49, in fun2
		    return fun1_2(x * 0)
		           ^^^^^^^^^^^^^
		  File ".../gen_stack.py", line 37, in fun1_2
		    return fun0_2(x) * 10
		           ^^^^^^^^^
		  File ".../gen_stack.py", line 33, in fun0_2
		    return 13 / x
		           ~~~^~~
		ZeroDivisionError: division by zero

	Total is 4709
	File cannot be accessed: /root/test/101 (PermissionError(13, 'Permission denied'))
	Total could not be written!
Processing 3
	Calling fun1_1
	Total is 8999
	Creating file: /home/pc/sciebo/Dokumente/Programming/recipe2txt/test/testfiles/permanent/logfiles/gen_log_res/4290
Processing 44
	Calling fun1_2
	Value caused ZeroDivisonError: 
		Traceback (most recent call last):
		  File ".../gen_log.py", line 72, in queue_processor
		    res = int(gen_stack.fun5(num))
		              ^^^^^^^^^^^^^^^^^^^
		  File ".../gen_stack.py", line 64, in fun5
		    return fun4(x) + 4321
		           ^^^^^^^
		  File ".../gen_stack.py", line 60, in fun4
		    return fun3(x) + 0.1
		           ^^^^^^^
		  File ".../gen_stack.py", line 56, in fun3
		    return fun2(x) * 4.56
		           ^^^^^^^
		  File ".../gen_stack.py", line 49, in fun2
		    return fun1_2(x * 0)
		           ^^^^^^^^^^^^^
		  File ".../gen_stack.py", line 37, in fun1_2
		    return fun0_2(x) * 10
		           ^^^^^^^^^
		  File ".../gen_stack.py", line 33, in fun0_2
		    return 13 / x
		           ~~~^~~
		ZeroDivisionError: division by zero

	Total is 9100
	File cannot be accessed: /root/test/101 (PermissionError(13, 'Permission denied'))
	Total could not be written!
Processing -19
	Calling fun1_1
	Value caused error: 
		Traceback (most recent call last):
		  File ".../gen_log.py", line 72, in queue_processor
		    res = int(gen_stack.fun5(num))
		              ^^^^^^^^^^^^^^^^^^^
		  File ".../gen_stack.py", line 64, in fun5
		    return fun4(x) + 4321
		           ^^^^^^^
		  File ".../gen_stack.py", line 60, in fun4
		    return fun3(x) + 0.1
		           ^^^^^^^
		  File ".../gen_stack.py", line 56, in fun3
		    return fun2(x) * 4.56
		           ^^^^^^^
		  File ".../gen_stack.py", line 52, in fun2
		    return fun1_1(x) - 12
		           ^^^^^^^^^
		  File ".../gen_stack.py", line 41, in fun1_1
		    return fun0_1(x) * 3
		           ^^^^^^^^^
		  File ".../gen_stack.py", line 29, in fun0_1
		    return sqrt(x)
		           ^^^^^^^
		ValueError: math domain error

	Total is 9302
Processing 2
	Calling fun1_1
	Total is 13587
	File cannot be accessed: /root/test/4285 (PermissionError(13, 'Permission denied'))
	Total could not be written!
Processing 1
	Calling fun1_1
	Total is 17867
	Creating file: /home/pc/sciebo/Dokumente/Programming/recipe2txt/test/testfiles/permanent/logfiles/gen_log_res/4280
Processing 6
	Calling fun1_1
	Total is 22166
	File cannot be accessed: /root/test/4299 (PermissionError(13, 'Permission denied'))
	Total could not be written!
	Reached the last element
The result of the calculations: 22166
